Workbook

Sheet allJGB
A1: orig | B1: path | C1: song_orig | D1: segue | E1: song1 | F1: song2 | G1: song3 | H1: song4
A2: 1 | B2: Z:\Jerry Garcia\1960-1969\jg1961-07-xx.017381.gh.aud.vernon.sbeok.t-flac16\garcia61-07-XXd1t01.flac | C2: Banjo Instrumental | D2: =IF(RIGHT(TRIM(C2),2)="->",">",IF(RIGHT(TRIM(C2),1)=">",">","")) | E2: =LOWER(TRIM(SUBSTITUTE(IF(RIGHT(TRIM(C2),2)="->",LEFT(TRIM(C2),LEN(TRIM(C2))-2),IF(RIGHT(TRIM(C2),1)=">",LEFT(TRIM(C2),LEN(TRIM(C2))-1),C2)),"//",""))) -> banjo instrumental | F2: banjo instrumental | G2: =_xlfn.IFNA(VLOOKUP(F2,songs!$B$1:$C$1539, 2, FALSE),"") | H2: Banjo
A3: 2 | B3: Z:\Jerry Garcia\1960-1969\jg1961-07-xx.017381.gh.aud.vernon.sbeok.t-flac16\garcia61-07-XXd1t02.flac | C3: Poor Ellen Smith | D3: =IF(RIGHT(TRIM(C3),2)="->",">",IF(RIGHT(TRIM(C3),1)=">",">","")) | E3: =LOWER(TRIM(SUBSTITUTE(IF(RIGHT(TRIM(C3),2)="->",LEFT(TRIM(C3),LEN(TRIM(C3))-2),IF(RIGHT(TRIM(C3),1)=">",LEFT(TRIM(C3),LEN(TRIM(C3))-1),C3)),"//",""))) -> poor ellen smith | F3: poor ellen smith | G3: =_xlfn.IFNA(VLOOKUP(F3,songs!$B$1:$C$1539, 2, FALSE),"") -> Poor Ellen Smith | H3: Poor Ellen Smith
A4: 3 | B4: Z:\Jerry Garcia\1960-1969\jg1961-07-xx.017381.gh.aud.vernon.sbeok.t-flac16\garcia61-07-XXd1t03.flac | C4: Wildwood Flower | D4: =IF(RIGHT(TRIM(C4),2)="->",">",IF(RIGHT(TRIM(C4),1)=">",">","")) | E4: =LOWER(TRIM(SUBSTITUTE(IF(RIGHT(TRIM(C4),2)="->",LEFT(TRIM(C4),LEN(TRIM(C4))-2),IF(RIGHT(TRIM(C4),1)=">",LEFT(TRIM(C4),LEN(TRIM(C4))-1),C4)),"//",""))) -> wildwood flower | F4: wildwood flower | G4: =_xlfn.IFNA(VLOOKUP(F4,songs!$B$1:$C$1539, 2, FALSE),"") -> Wildwood Flower | H4: Wildwood Flower
A5: 4 | B5: Z:\Jerry Garcia\1960-1969\jg1961-07-xx.017381.gh.aud.vernon.sbeok.t-flac16\garcia61-07-XXd1t04.flac | C5: Brown's Ferry Blues | D5: =IF(RIGHT(TRIM(C5),2)="->",">",IF(RIGHT(TRIM(C5),1)=">",">","")) | E5: =LOWER(TRIM(SUBSTITUTE(IF(RIGHT(TRIM(C5),2)="->",LEFT(TRIM(C5),LEN(TRIM(C5))-2),IF(RIGHT(TRIM(C5),1)=">",LEFT(TRIM(C5),LEN(TRIM(C5))-1),C5)),"//",""))) -> brown's ferry blues | F5: brown's ferry blues | G5: =_xlfn.IFNA(VLOOKUP(F5,songs!$B$1:$C$1539, 2, FALSE),"") -> Brown's Ferry Blues | H5: Brown's Ferry Blues
A6: 5 | B6: Z:\Jerry Garcia\1960-1969\jg1961-07-xx.017381.gh.aud.vernon.sbeok.t-flac16\garcia61-07-XXd1t05.flac | C6: Jesse James | D6: =IF(RIGHT(TRIM(C6),2)="->",">",IF(RIGHT(TRIM(C6),1)=">",">","")) | E6: =LOWER(TRIM(SUBSTITUTE(IF(RIGHT(TRIM(C6),2)="->",LEFT(TRIM(C6),LEN(TRIM(C6))-2),IF(RIGHT(TRIM(C6),1)=">",LEFT(TRIM(C6),LEN(TRIM(C6))-1),C6)),"//",""))) -> jesse james | F6: jesse james | G6: =_xlfn.IFNA(VLOOKUP(F6,songs!$B$1:$C$1539, 2, FALSE),"") -> Jesse James | H6: Jesse James
A7: 6 | B7: Z:\Jerry Garcia\1960-1969\jg1961-07-xx.017381.gh.aud.vernon.sbeok.t-flac16\garcia61-07-XXd1t06.flac | C7: Late Last Night When Willie Came Home | D7: =IF(RIGHT(TRIM(C7),2)="->",">",IF(RIGHT(TRIM(C7),1)=">",">","")) | E7: =LOWER(TRIM(SUBSTITUTE(IF(RIGHT(TRIM(C7),2)="->",LEFT(TRIM(C7),LEN(TRIM(C7))-2),IF(RIGHT(TRIM(C7),1)=">",LEFT(TRIM(C7),LEN(TRIM(C7))-1),C7)),"//",""))) -> late last night when willie came home | F7: late last night when willie came home | G7: =_xlfn.IFNA(VLOOKUP(F7,songs!$B$1:$C$1539, 2, FALSE),"") -> Late Last Night When Willie Came Home | H7: Late Last Night When Willie Came Home
A8: 7 | B8: Z:\Jerry Garcia\1960-1969\jg1961-07-xx.017381.gh.aud.vernon.sbeok.t-flac16\garcia61-07-XXd1t07.flac | C8: All the Good Times Are Passed and Gone | D8: =IF(RIGHT(TRIM(C8),2)="->",">",IF(RIGHT(TRIM(C8),1)=">",">","")) | E8: =LOWER(TRIM(SUBSTITUTE(IF(RIGHT(TRIM(C8),2)="->",LEFT(TRIM(C8),LEN(TRIM(C8))-2),IF(RIGHT(TRIM(C8),1)=">",LEFT(TRIM(C8),LEN(TRIM(C8))-1),C8)),"//",""))) -> all the good times are passed and gone | F8: all the good times are passed and gone | G8: =_xlfn.IFNA(VLOOKUP(F8,songs!$B$1:$C$1539, 2, FALSE),"") | H8: All The Good Times Are Past And Gone
A9: 8 | B9: Z:\Jerry Garcia\1960-1969\jg1961-07-xx.017381.gh.aud.vernon.sbeok.t-flac16\garcia61-07-XXd1t08.flac | C9: Darling Corey | D9: =IF(RIGHT(TRIM(C9),2)="->",">",IF(RIGHT(TRIM(C9),1)=">",">","")) | E9: =LOWER(TRIM(SUBSTITUTE(IF(RIGHT(TRIM(C9),2)="->",LEFT(TRIM(C9),LEN(TRIM(C9))-2),IF(RIGHT(TRIM(C9),1)=">",LEFT(TRIM(C9),LEN(TRIM(C9))-1),C9)),"//",""))) -> darling corey | F9: darling corey | G9: =_xlfn.IFNA(VLOOKUP(F9,songs!$B$1:$C$1539, 2, FALSE),"") | H9: Darlin' Corey
A10: 9 | B10: Z:\Jerry Garcia\1960-1969\jg1961-07-xx.017381.gh.aud.vernon.sbeok.t-flac16\garcia61-07-XXd1t09.flac | C10: The Ballad of Harry Pollitt | D10: =IF(RIGHT(TRIM(C10),2)="->",">",IF(RIGHT(TRIM(C10),1)=">",">","")) | E10: =LOWER(TRIM(SUBSTITUTE(IF(RIGHT(TRIM(C10),2)="->",LEFT(TRIM(C10),LEN(TRIM(C10))-2),IF(RIGHT(TRIM(C10),1)=">",LEFT(TRIM(C10),LEN(TRIM(C10))-1),C10)),"//",""))) -> the ballad of harry pollitt | F10: the ballad of harry pollitt | G10: =_xlfn.IFNA(VLOOKUP(F10,songs!$B$1:$C$1539, 2, FALSE),"") | H10: The Ballad Of Harry Pollitt
A11: 10 | B11: Z:\Jerry Garcia\1960-1969\jg1961-64.130666.compilation.droncit.flac16\garcia1961-7-xx.t01.flac | C11: Banjo Instrumental | D11: =IF(RIGHT(TRIM(C11),2)="->",">",IF(RIGHT(TRIM(C11),1)=">",">","")) | E11: =LOWER(TRIM(SUBSTITUTE(IF(RIGHT(TRIM(C11),2)="->",LEFT(TRIM(C11),LEN(TRIM(C11))-2),IF(RIGHT(TRIM(C11),1)=">",LEFT(TRIM(C11),LEN(TRIM(C11))-1),C11)),"//",""))) -> banjo instrumental | F11: banjo instrumental | G11: =_xlfn.IFNA(VLOOKUP(F11,songs!$B$1:$C$1539, 2, FALSE),"") | H11: Banjo
A12: 11 | B12: Z:\Jerry Garcia\1960-1969\jg1961-64.130666.compilation.droncit.flac16\garcia1961-7-xx.t02.flac | C12: Poor Ellen Smith | D12: =IF(RIGHT(TRIM(C12),2)="->",">",IF(RIGHT(TRIM(C12),1)=">",">","")) | E12: =LOWER(TRIM(SUBSTITUTE(IF(RIGHT(TRIM(C12),2)="->",LEFT(TRIM(C12),LEN(TRIM(C12))-2),IF(RIGHT(TRIM(C12),1)=">",LEFT(TRIM(C12),LEN(TRIM(C12))-1),C12)),"//",""))) -> poor ellen smith | F12: poor ellen smith | G12: =_xlfn.IFNA(VLOOKUP(F12,songs!$B$1:$C$1539, 2, FALSE),"") -> Poor Ellen Smith | H12: Poor Ellen Smith
A13: 12 | B13: Z:\Jerry Garcia\1960-1969\jg1961-64.130666.compilation.droncit.flac16\garcia1961-7-xx.t03.flac | C13: Wildwood Flower | D13: =IF(RIGHT(TRIM(C13),2)="->",">",IF(RIGHT(TRIM(C13),1)=">",">","")) | E13: =LOWER(TRIM(SUBSTITUTE(IF(RIGHT(TRIM(C13),2)="->",LEFT(TRIM(C13),LEN(TRIM(C13))-2),IF(RIGHT(TRIM(C13),1)=">",LEFT(TRIM(C13),LEN(TRIM(C13))-1),C13)),"//",""))) -> wildwood flower | F13: wildwood flower | G13: =_xlfn.IFNA(VLOOKUP(F13,songs!$B$1:$C$1539, 2, FALSE),"") -> Wildwood Flower | H13: Wildwood Flower
... A121: 120 | B121: Z:\Jerry Garcia\1960-1969\jg1962-11-10,143683.csmff.aud.albin.miksis.t-flac16\223 Salty Dog Blues.flac | C121: Salty Dog Blues | D121: =IF(RIGHT(TRIM(C121),2)="->",">",IF(RIGHT(TRIM(C121),1)=">",">","")) | E121: =LOWER(TRIM(SUBSTITUTE(IF(RIGHT(TRIM(C121),2)="->",LEFT(TRIM(C121),LEN(TRIM(C121))-2),IF(RIGHT(TRIM(C121),1)=">",LEFT(TRIM(C121),LEN(TRIM(C121))-1),C121)),"//",""))) -> salty dog blues | F121: salty dog blues | G121: =_xlfn.IFNA(VLOOKUP(F121,songs!$B$1:$C$1539, 2, FALSE),"") -> Salty Dog Blues | H121: Salty Dog Blues
A122: 121 | B122: Z:\Jerry Garcia\1960-1969\jg1962-11-10,143683.csmff.aud.albin.miksis.t-flac16\224 Let Me Fly.flac | C122: Let Me Fly | D122: =IF(RIGHT(TRIM(C122),2)="->",">",IF(RIGHT(TRIM(C122),1)=">",">","")) | E122: =LOWER(TRIM(SUBSTITUTE(IF(RIGHT(TRIM(C122),2)="->",LEFT(TRIM(C122),LEN(TRIM(C122))-2),IF(RIGHT(TRIM(C122),1)=">",LEFT(TRIM(C122),LEN(TRIM(C122))-1),C122)),"//",""))) -> let me fly | F122: let me fly | G122: =_xlfn.IFNA(VLOOKUP(F122,songs!$B$1:$C$1539, 2, FALSE),"")
A123: 122 | B123: Z:\Jerry Garcia\1960-1969\jg1962-11-10,143683.csmff.aud.albin.miksis.t-flac16\225 Rollin' Stone.flac | C123: Rollin' Stone | D123: =IF(RIGHT(TRIM(C123),2)="->",">",IF(RIGHT(TRIM(C123),1)=">",">","")) | E123: =LOWER(TRIM(SUBSTITUTE(IF(RIGHT(TRIM(C123),2)="->",LEFT(TRIM(C123),LEN(TRIM(C123))-2),IF(RIGHT(TRIM(C123),1)=">",LEFT(TRIM(C123),LEN(TRIM(C123))-1),C123)),"//",""))) -> rollin' stone | F123: rollin' stone | G123: =_xlfn.IFNA(VLOOKUP(F123,songs!$B$1:$C$1539, 2, FALSE),"") | H123: Rollin' Stone
A124: 123 | B124: Z:\Jerry Garcia\1960-1969\jg1962-11-10,143683.csmff.aud.albin.miksis.t-flac16\226 If I Had a Hammer.flac | C124: If I Had a Hammer | D124: =IF(RIGHT(TRIM(C124),2)="->",">",IF(RIGHT(TRIM(C124),1)=">",">","")) | E124: =LOWER(TRIM(SUBSTITUTE(IF(RIGHT(TRIM(C124),2)="->",LEFT(TRIM(C124),LEN(TRIM(C124))-2),IF(RIGHT(TRIM(C124),1)=">",LEFT(TRIM(C124),LEN(TRIM(C124))-1),C124)),"//",""))) -> if i had a hammer | F124: if i had a hammer | G124: =_xlfn.IFNA(VLOOKUP(F124,songs!$B$1:$C$1539, 2, FALSE),"") | H124: If I Had A Hammer
A125: 124 | B125: Z:\Jerry Garcia\1960-1969\jg1962-11-10,143683.csmff.aud.albin.miksis.t-flac16\227 Jesse James (w_ Ken Armstrong on banjo).flac | C125: Jesse James | D125: =IF(RIGHT(TRIM(C125),2)="->",">",IF(RIGHT(TRIM(C125),1)=">",">","")) | E125: =LOWER(TRIM(SUBSTITUTE(IF(RIGHT(TRIM(C125),2)="->",LEFT(TRIM(C125),LEN(TRIM(C125))-2),IF(RIGHT(TRIM(C125),1)=">",LEFT(TRIM(C125),LEN(TRIM(C125))-1),C125)),"//",""))) -> jesse james | F125: jesse james | G125: =_xlfn.IFNA(VLOOKUP(F125,songs!$B$1:$C$1539, 2, FALSE),"") -> Jesse James | H125: Jesse James
A126: 125 | B126: Z:\Jerry Garcia\1960-1969\jg1962-11-10,143683.csmff.aud.albin.miksis.t-flac16\228 unknown.flac | C126: unknown | D126: =IF(RIGHT(TRIM(C126),2)="->",">",IF(RIGHT(TRIM(C126),1)=">",">","")) | E126: =LOWER(TRIM(SUBSTITUTE(IF(RIGHT(TRIM(C126),2)="->",LEFT(TRIM(C126),LEN(TRIM(C126))-2),IF(RIGHT(TRIM(C126),1)=">",LEFT(TRIM(C126),LEN(TRIM(C126))-1),C126)),"//",""))) -> unknown | F126: unknown | G126: =_xlfn.IFNA(VLOOKUP(F126,songs!$B$1:$C$1539, 2, FALSE),"") | H126: Unknown
A127: 126 | B127: Z:\Jerry Garcia\1960-1969\jg1962-11-10,143683.csmff.aud.albin.miksis.t-flac16\229 Scotch and Soda.flac | C127: Scotch and Soda | D127: =IF(RIGHT(TRIM(C127),2)="->",">",IF(RIGHT(TRIM(C127),1)=">",">","")) | E127: =LOWER(TRIM(SUBSTITUTE(IF(RIGHT(TRIM(C127),2)="->",LEFT(TRIM(C127),LEN(TRIM(C127))-2),IF(RIGHT(TRIM(C127),1)=">",LEFT(TRIM(C127),LEN(TRIM(C127))-1),C127)),"//",""))) -> scotch and soda | F127: scotch and soda | G127: =_xlfn.IFNA(VLOOKUP(F127,songs!$B$1:$C$1539, 2, FALSE),"") | H127: Scotch And Soda
A128: 127 | B128: Z:\Jerry Garcia\1960-1969\jg1962-11-10,143683.csmff.aud.albin.miksis.t-flac16\230 Mountain Dew.flac | C128: Mountain Dew | D128: =IF(RIGHT(TRIM(C128),2)="->",">",IF(RIGHT(TRIM(C128),1)=">",">","")) | E128: =LOWER(TRIM(SUBSTITUTE(IF(RIGHT(TRIM(C128),2)="->",LEFT(TRIM(C128),LEN(TRIM(C128))-2),IF(RIGHT(TRIM(C128),1)=">",LEFT(TRIM(C128),LEN(TRIM(C128))-1),C128)),"//",""))) -> mountain dew | F128: mountain dew | G128: =_xlfn.IFNA(VLOOKUP(F128,songs!$B$1:$C$1539, 2, FALSE),"") | H128: Mountain Dew
A129: 128 | B129: Z:\Jerry Garcia\1960-1969\jg1963-02-23.004501.wb.aud.fm-mogol.sbeok.t-flac16\garcia1963-02-23t01.flac | C129: introduction | D129: =IF(RIGHT(TRIM(C129),2)="->",">",IF(RIGHT(TRIM(C129),1)=">",">","")) | E129: =LOWER(TRIM(SUBSTITUTE(IF(RIGHT(TRIM(C129),2)="->",LEFT(TRIM(C129),LEN(TRIM(C129))-2),IF(RIGHT(TRIM(C129),1)=">",LEFT(TRIM(C129),LEN(TRIM(C129))-1),C129)),"//",""))) -> introduction | F129: introduction | G129: =_xlfn.IFNA(VLOOKUP(F129,songs!$B$1:$C$1539, 2, FALSE),"") | H129: Introduction
A130: 129 | B130: Z:\Jerry Garcia\1960-1969\jg1963-02-23.004501.wb.aud.fm-mogol.sbeok.t-flac16\garcia1963-02-23t02.flac | C130: Rollin' in My Sweet Babys Arms | D130: =IF(RIGHT(TRIM(C130),2)="->",">",IF(RIGHT(TRIM(C130),1)=">",">","")) | E130: =LOWER(TRIM(SUBSTITUTE(IF(RIGHT(TRIM(C130),2)="->",LEFT(TRIM(C130),LEN(TRIM(C130))-2),IF(RIGHT(TRIM(C130),1)=">",LEFT(TRIM(C130),LEN(TRIM(C130))-1),C130)),"//",""))) -> rollin' in my sweet babys arms | F130: rollin' in my sweet babys arms | G130: =_xlfn.IFNA(VLOOKUP(F130,songs!$B$1:$C$1539, 2, FALSE),"") | H130: Roll In My Sweet Baby's Arms
A131: 130 | B131: Z:\Jerry Garcia\1960-1969\jg1963-02-23.004501.wb.aud.fm-mogol.sbeok.t-flac16\garcia1963-02-23t03.flac | C131: Jerry's Breakdown | D131: =IF(RIGHT(TRIM(C131),2)="->",">",IF(RIGHT(TRIM(C131),1)=">",">","")) | E131: =LOWER(TRIM(SUBSTITUTE(IF(RIGHT(TRIM(C131),2)="->",LEFT(TRIM(C131),LEN(TRIM(C131))-2),IF(RIGHT(TRIM(C131),1)=">",LEFT(TRIM(C131),LEN(TRIM(C131))-1),C131)),"//",""))) -> jerry's breakdown | F131: jerry's breakdown | G131: =_xlfn.IFNA(VLOOKUP(F131,songs!$B$1:$C$1539, 2, FALSE),"") | H131: Jerry's Breakdown (1963)
A132: 131 | B132: Z:\Jerry Garcia\1960-1969\jg1963-02-23.004501.wb.aud.fm-mogol.sbeok.t-flac16\garcia1963-02-23t04.flac | C132: Standing in the Need of Prayer | D132: =IF(RIGHT(TRIM(C132),2)="->",">",IF(RIGHT(TRIM(C132),1)=">",">","")) | E132: =LOWER(TRIM(SUBSTITUTE(IF(RIGHT(TRIM(C132),2)="->",LEFT(TRIM(C132),LEN(TRIM(C132))-2),IF(RIGHT(TRIM(C132),1)=">",LEFT(TRIM(C132),LEN(TRIM(C132))-1),C132)),"//",""))) -> standing in the need of prayer | F132: standing in the need of prayer | G132: =_xlfn.IFNA(VLOOKUP(F132,songs!$B$1:$C$1539, 2, FALSE),"") -> Standing In The Need Of Prayer | H132: Standing In The Need Of Prayer
A133: 132 | B133: Z:\Jerry Garcia\1960-1969\jg1963-02-23.004501.wb.aud.fm-mogol.sbeok.t-flac16\garcia1963-02-23t05.flac | C133: Mule Skinner Blues | D133: =IF(RIGHT(TRIM(C133),2)="->",">",IF(RIGHT(TRIM(C133),1)=">",">","")) | E133: =LOWER(TRIM(SUBSTITUTE(IF(RIGHT(TRIM(C133),2)="->",LEFT(TRIM(C133),LEN(TRIM(C133))-2),IF(RIGHT(TRIM(C133),1)=">",LEFT(TRIM(C133),LEN(TRIM(C133))-1),C133)),"//",""))) -> mule skinner blues | F133: mule skinner blues | G133: =_xlfn.IFNA(VLOOKUP(F133,songs!$B$1:$C$1539, 2, FALSE),"") -> Mule Skinner Blues | H133: Mule Skinner Blues
A134: 133 | B134: Z:\Jerry Garcia\1960-1969\jg1963-02-23.004501.wb.aud.fm-mogol.sbeok.t-flac16\garcia1963-02-23t06.flac | C134: Guitar Instrumental | D134: =IF(RIGHT(TRIM(C134),2)="->",">",IF(RIGHT(TRIM(C134),1)=">",">","")) | E134: =LOWER(TRIM(SUBSTITUTE(IF(RIGHT(TRIM(C134),2)="->",LEFT(TRIM(C134),LEN(TRIM(C134))-2),IF(RIGHT(TRIM(C134),1)=">",LEFT(TRIM(C134),LEN(TRIM(C134))-1),C134)),"//",""))) -> guitar instrumental | F134: guitar instrumental | G134: =_xlfn.IFNA(VLOOKUP(F134,songs!$B$1:$C$1539, 2, FALSE),"") | H134: Instrumental
A135: 134 | B135: Z:\Jerry Garcia\1960-1969\jg1963-02-23.004501.wb.aud.fm-mogol.sbeok.t-flac16\garcia1963-02-23t07.flac | C135: Pike County Breakdown | D135: =IF(RIGHT(TRIM(C135),2)="->",">",IF(RIGHT(TRIM(C135),1)=">",">","")) | E135: =LOWER(TRIM(SUBSTITUTE(IF(RIGHT(TRIM(C135),2)="->",LEFT(TRIM(C135),LEN(TRIM(C135))-2),IF(RIGHT(TRIM(C135),1)=">",LEFT(TRIM(C135),LEN(TRIM(C135))-1),C135)),"//",""))) -> pike county breakdown | F135: pike county breakdown | G135: =_xlfn.IFNA(VLOOKUP(F135,songs!$B$1:$C$1539, 2, FALSE),"") -> Pike County Breakdown | H135: Pike County Breakdown
A136: 135 | B136: Z:\Jerry Garcia\1960-1969\jg1963-02-23.004501.wb.aud.fm-mogol.sbeok.t-flac16\garcia1963-02-23t08.flac | C136: Come All Ye Fair and Tender Maidens | D136: =IF(RIGHT(TRIM(C136),2)="->",">",IF(RIGHT(TRIM(C136),1)=">",">","")) | E136: =LOWER(TRIM(SUBSTITUTE(IF(RIGHT(TRIM(C136),2)="->",LEFT(TRIM(C136),LEN(TRIM(C136))-2),IF(RIGHT(TRIM(C136),1)=">",LEFT(TRIM(C136),LEN(TRIM(C136))-1),C136)),"//",""))) -> come all ye fair and tender maidens | F136: come all ye fair and tender maidens | G136: =_xlfn.IFNA(VLOOKUP(F136,songs!$B$1:$C$1539, 2, FALSE),"")
A137: 136 | B137: Z:\Jerry Garcia\1960-1969\jg1963-02-23.004501.wb.aud.fm-mogol.sbeok.t-flac16\garcia1963-02-23t09.flac | C137: We Shall Not Be Moved | D137: =IF(RIGHT(TRIM(C137),2)="->",">",IF(RIGHT(TRIM(C137),1)=">",">","")) | E137: =LOWER(TRIM(SUBSTITUTE(IF(RIGHT(TRIM(C137),2)="->",LEFT(TRIM(C137),LEN(TRIM(C137))-2),IF(RIGHT(TRIM(C137),1)=">",LEFT(TRIM(C137),LEN(TRIM(C137))-1),C137)),"//",""))) -> we shall not be moved | F137: we shall not be moved | G137: =_xlfn.IFNA(VLOOKUP(F137,songs!$B$1:$C$1539, 2, FALSE),"") -> We Shall Not Be Moved | H137: We Shall Not Be Moved
A138: 137 | B138: Z:\Jerry Garcia\1960-1969\jg1963-05-04.013993.jgsg.fm.t-flac16\jg1963-05-04d1t01.flac | C138: Deep Elem Blues | D138: =IF(RIGHT(TRIM(C138),2)="->",">",IF(RIGHT(TRIM(C138),1)=">",">","")) | E138: =LOWER(TRIM(SUBSTITUTE(IF(RIGHT(TRIM(C138),2)="->",LEFT(TRIM(C138),LEN(TRIM(C138))-2),IF(RIGHT(TRIM(C138),1)=">",LEFT(TRIM(C138),LEN(TRIM(C138))-1),C138)),"//",""))) -> deep elem blues | F138: deep elem blues | G138: =_xlfn.IFNA(VLOOKUP(F138,songs!$B$1:$C$1539, 2, FALSE),"") -> Deep Elem Blues | H138: Deep Elem Blues
A139: 138 | B139: Z:\Jerry Garcia\1960-1969\jg1963-05-04.013993.jgsg.fm.t-flac16\jg1963-05-04d1t02.flac | C139: Will the Weaver | D139: =IF(RIGHT(TRIM(C139),2)="->",">",IF(RIGHT(TRIM(C139),1)=">",">","")) | E139: =LOWER(TRIM(SUBSTITUTE(IF(RIGHT(TRIM(C139),2)="->",LEFT(TRIM(C139),LEN(TRIM(C139))-2),IF(RIGHT(TRIM(C139),1)=">",LEFT(TRIM(C139),LEN(TRIM(C139))-1),C139)),"//",""))) -> will the weaver | F139: will the weaver | G139: =_xlfn.IFNA(VLOOKUP(F139,songs!$B$1:$C$1539, 2, FALSE),"") -> Will The Weaver | H139: Will The Weaver
A140: 139 | B140: Z:\Jerry Garcia\1960-1969\jg1963-05-04.013993.jgsg.fm.t-flac16\jg1963-05-04d1t03.flac | C140: I Truly Understand | D140: =IF(RIGHT(TRIM(C140),2)="->",">",IF(RIGHT(TRIM(C140),1)=">",">","")) | E140: =LOWER(TRIM(SUBSTITUTE(IF(RIGHT(TRIM(C140),2)="->",LEFT(TRIM(C140),LEN(TRIM(C140))-2),IF(RIGHT(TRIM(C140),1)=">",LEFT(TRIM(C140),LEN(TRIM(C140))-1),C140)),"//",""))) -> i truly understand | F140: i truly understand | G140: =_xlfn.IFNA(VLOOKUP(F140,songs!$B$1:$C$1539, 2, FALSE),"") -> I Truly Understand | H140: I Truly Understand
A141: 140 | B141: Z:\Jerry Garcia\1960-1969\jg1963-05-04.013993.jgsg.fm.t-flac16\jg1963-05-04d1t04.flac | C141: All the Good Times Are Passed and Gone | D141: =IF(RIGHT(TRIM(C141),2)="->",">",IF(RIGHT(TRIM(C141),1)=">",">","")) | E141: =LOWER(TRIM(SUBSTITUTE(IF(RIGHT(TRIM(C141),2)="->",LEFT(TRIM(C141),LEN(TRIM(C141))-2),IF(RIGHT(TRIM(C141),1)=">",LEFT(TRIM(C141),LEN(TRIM(C141))-1),C141)),"//",""))) -> all the good times are passed and gone | F141: all the good times are passed and gone | G141: =_xlfn.IFNA(VLOOKUP(F141,songs!$B$1:$C$1539, 2, FALSE),"") | H141: All The Good Times Are Past And Gone
A142: 141 | B142: Z:\Jerry Garcia\1960-1969\jg1963-05-04.013993.jgsg.fm.t-flac16\jg1963-05-04d1t05.flac | C142: Long Black Veil | D142: =IF(RIGHT(TRIM(C142),2)="->",">",IF(RIGHT(TRIM(C142),1)=">",">","")) | E142: =LOWER(TRIM(SUBSTITUTE(IF(RIGHT(TRIM(C142),2)="->",LEFT(TRIM(C142),LEN(TRIM(C142))-2),IF(RIGHT(TRIM(C142),1)=">",LEFT(TRIM(C142),LEN(TRIM(C142))-1),C142)),"//",""))) -> long black veil | F142: long black veil | G142: =_xlfn.IFNA(VLOOKUP(F142,songs!$B$1:$C$1539, 2, FALSE),"") -> Long Black Veil | H142: Long Black Veil
A143: 142 | B143: Z:\Jerry Garcia\1960-1969\jg1963-05-04.013993.jgsg.fm.t-flac16\jg1963-05-04d1t06.flac | C143: The Man Who Wrote Home Sweet Home Never Was a Married Man | D143: =IF(RIGHT(TRIM(C143),2)="->",">",IF(RIGHT(TRIM(C143),1)=">",">","")) | E143: =LOWER(TRIM(SUBSTITUTE(IF(RIGHT(TRIM(C143),2)="->",LEFT(TRIM(C143),LEN(TRIM(C143))-2),IF(RIGHT(TRIM(C143),1)=">",LEFT(TRIM(C143),LEN(TRIM(C143))-1),C143)),"//",""))) -> the man who wrote home sweet home never was a married man | F143: the man who wrote home sweet home never was a married man | G143: =_xlfn.IFNA(VLOOKUP(F143,songs!$B$1:$C$1539, 2, FALSE),"") -> The Man Who Wrote Home Sweet Home Never Was a Married Man | H143: The Man Who Wrote Home Sweet Home Never Was a Married Man
A144: 143 | B144: Z:\Jerry Garcia\1960-1969\jg1963-05-04.013993.jgsg.fm.t-flac16\jg1963-05-04d1t07.flac | C144: Keno, the Rent Man | D144: =IF(RIGHT(TRIM(C144),2)="->",">",IF(RIGHT(TRIM(C144),1)=">",">","")) | E144: =LOWER(TRIM(SUBSTITUTE(IF(RIGHT(TRIM(C144),2)="->",LEFT(TRIM(C144),LEN(TRIM(C144))-2),IF(RIGHT(TRIM(C144),1)=">",LEFT(TRIM(C144),LEN(TRIM(C144))-1),C144)),"//",""))) -> keno, the rent man | F144: keno, the rent man | G144: =_xlfn.IFNA(VLOOKUP(F144,songs!$B$1:$C$1539, 2, FALSE),"") | H144: Keno The Rent Man
A145: 144 | B145: Z:\Jerry Garcia\1960-1969\jg1963-05-04.013993.jgsg.fm.t-flac16\jg1963-05-04d1t08.flac | C145: Foggy Mountain Top | D145: =IF(RIGHT(TRIM(C145),2)="->",">",IF(RIGHT(TRIM(C145),1)=">",">","")) | E145: =LOWER(TRIM(SUBSTITUTE(IF(RIGHT(TRIM(C145),2)="->",LEFT(TRIM(C145),LEN(TRIM(C145))-2),IF(RIGHT(TRIM(C145),1)=">",LEFT(TRIM(C145),LEN(TRIM(C145))-1),C145)),"//",""))) -> foggy mountain top | F145: foggy mountain top | G145: =_xlfn.IFNA(VLOOKUP(F145,songs!$B$1:$C$1539, 2, FALSE),"") -> Foggy Mountain Top | H145: Foggy Mountain Top
A146: 145 | B146: Z:\Jerry Garcia\1960-1969\jg1964-03-06.017914.bmb.sbd.backus-wagner.sbeok.t-flac16\bmb1964-03-06t01.flac | C146: Salt Creek | D146: =IF(RIGHT(TRIM(C146),2)="->",">",IF(RIGHT(TRIM(C146),1)=">",">","")) | E146: =LOWER(TRIM(SUBSTITUTE(IF(RIGHT(TRIM(C146),2)="->",LEFT(TRIM(C146),LEN(TRIM(C146))-2),IF(RIGHT(TRIM(C146),1)=">",LEFT(TRIM(C146),LEN(TRIM(C146))-1),C146)),"//",""))) -> salt creek | F146: salt creek | G146: =_xlfn.IFNA(VLOOKUP(F146,songs!$B$1:$C$1539, 2, FALSE),"") -> Salt Creek | H146: Salt Creek
A147: 146 | B147: Z:\Jerry Garcia\1960-1969\jg1964-03-06.017914.bmb.sbd.backus-wagner.sbeok.t-flac16\bmb1964-03-06t02.flac | C147: Katie Kline | D147: =IF(RIGHT(TRIM(C147),2)="->",">",IF(RIGHT(TRIM(C147),1)=">",">","")) | E147: =LOWER(TRIM(SUBSTITUTE(IF(RIGHT(TRIM(C147),2)="->",LEFT(TRIM(C147),LEN(TRIM(C147))-2),IF(RIGHT(TRIM(C147),1)=">",LEFT(TRIM(C147),LEN(TRIM(C147))-1),C147)),"//",""))) -> katie kline | F147: katie kline | G147: =_xlfn.IFNA(VLOOKUP(F147,songs!$B$1:$C$1539, 2, FALSE),"") -> Katie Kline | H147: Katie Kline
...

Sheet songs
A1: 1501 | B1: (back home again in) indiana | C1: (Back Home Again In) Indiana
A2: 500 | B2: (i'm a) road runner | C2: (I'm A) Road Runner
A3: 935 | B3: 16/16 | C3: 16/16
A4: 1629 | B4: 23rd psalm | C4: 23rd Psalm
A5: 35 | B5: 3 o'clock in the morning blues | C5: 3 O'Clock In The Morning Blues
A6: 817 | B6: a cry from the cross | C6: A Cry From The Cross
A7: 1709 | B7: a day in the life | C7: A Day In the Life
A8: 1555 | B8: a good man is hard to find | C8: A Good Man Is Hard To Find
A9: 479 | B9: a good woman's love | C9: A Good Woman's Love
A10: 370 | B10: a hard rain's a-gonna fall | C10: A Hard Rain's A-Gonna Fall
A11: 815 | B11: a little at a time | C11: A Little At A Time
A12: 1213 | B12: a mind to give up livin' | C12: A Mind To Give Up Livin'
... A1539: 894 | B1539: zillionaire | C1539: Zillionaire

Sheet Export
A1: Z:\Jerry Garcia\1960-1969\jg1961-07-xx.017381.gh.aud.vernon.sbeok.t-flac16\garcia61-07-XXd1t01.flac | B1: | | C1: Banjo | D1: |
A2: Z:\Jerry Garcia\1960-1969\jg1961-07-xx.017381.gh.aud.vernon.sbeok.t-flac16\garcia61-07-XXd1t02.flac | B2: | | C2: Poor Ellen Smith | D2: |
A3: Z:\Jerry Garcia\1960-1969\jg1961-07-xx.017381.gh.aud.vernon.sbeok.t-flac16\garcia61-07-XXd1t03.flac | B3: | | C3: Wildwood Flower | D3: |
A4: Z:\Jerry Garcia\1960-1969\jg1961-07-xx.017381.gh.aud.vernon.sbeok.t-flac16\garcia61-07-XXd1t04.flac | B4: | | C4: Brown's Ferry Blues | D4: |
A5: Z:\Jerry Garcia\1960-1969\jg1961-07-xx.017381.gh.aud.vernon.sbeok.t-flac16\garcia61-07-XXd1t05.flac | B5: | | C5: Jesse James | D5: |
A6: Z:\Jerry Garcia\1960-1969\jg1961-07-xx.017381.gh.aud.vernon.sbeok.t-flac16\garcia61-07-XXd1t06.flac | B6: | | C6: Late Last Night When Willie Came Home | D6: |
A7: Z:\Jerry Garcia\1960-1969\jg1961-07-xx.017381.gh.aud.vernon.sbeok.t-flac16\garcia61-07-XXd1t07.flac | B7: | | C7: All The Good Times Are Past And Gone | D7: |
A8: Z:\Jerry Garcia\1960-1969\jg1961-07-xx.017381.gh.aud.vernon.sbeok.t-flac16\garcia61-07-XXd1t08.flac | B8: | | C8: Darlin' Corey | D8: |
A9: Z:\Jerry Garcia\1960-1969\jg1961-07-xx.017381.gh.aud.vernon.sbeok.t-flac16\garcia61-07-XXd1t09.flac | B9: | | C9: The Ballad Of Harry Pollitt | D9: |
A10: Z:\Jerry Garcia\1960-1969\jg1961-64.130666.compilation.droncit.flac16\garcia1961-7-xx.t01.flac | B10: | | C10: Banjo | D10: |
A11: Z:\Jerry Garcia\1960-1969\jg1961-64.130666.compilation.droncit.flac16\garcia1961-7-xx.t02.flac | B11: | | C11: Poor Ellen Smith | D11: |
A12: Z:\Jerry Garcia\1960-1969\jg1961-64.130666.compilation.droncit.flac16\garcia1961-7-xx.t03.flac | B12: | | C12: Wildwood Flower | D12: |
... A120: Z:\Jerry Garcia\1960-1969\jg1962-11-10,143683.csmff.aud.albin.miksis.t-flac16\223 Salty Dog Blues.flac | B120: | | C120: Salty Dog Blues | D120: |
A121: Z:\Jerry Garcia\1960-1969\jg1962-11-10,143683.csmff.aud.albin.miksis.t-flac16\224 Let Me Fly.flac | B121: | | D121: |
A122: Z:\Jerry Garcia\1960-1969\jg1962-11-10,143683.csmff.aud.albin.miksis.t-flac16\225 Rollin' Stone.flac | B122: | | C122: Rollin' Stone | D122: |
A123: Z:\Jerry Garcia\1960-1969\jg1962-11-10,143683.csmff.aud.albin.miksis.t-flac16\226 If I Had a Hammer.flac | B123: | | C123: If I Had A Hammer | D123: |
A124: Z:\Jerry Garcia\1960-1969\jg1962-11-10,143683.csmff.aud.albin.miksis.t-flac16\227 Jesse James (w_ Ken Armstrong on banjo).flac | B124: | | C124: Jesse James | D124: |
A125: Z:\Jerry Garcia\1960-1969\jg1962-11-10,143683.csmff.aud.albin.miksis.t-flac16\228 unknown.flac | B125: | | C125: Unknown | D125: |
A126: Z:\Jerry Garcia\1960-1969\jg1962-11-10,143683.csmff.aud.albin.miksis.t-flac16\229 Scotch and Soda.flac | B126: | | C126: Scotch And Soda | D126: |
A127: Z:\Jerry Garcia\1960-1969\jg1962-11-10,143683.csmff.aud.albin.miksis.t-flac16\230 Mountain Dew.flac | B127: | | C127: Mountain Dew | D127: |
A128: Z:\Jerry Garcia\1960-1969\jg1963-02-23.004501.wb.aud.fm-mogol.sbeok.t-flac16\garcia1963-02-23t01.flac | B128: | | C128: Introduction | D128: |
A129: Z:\Jerry Garcia\1960-1969\jg1963-02-23.004501.wb.aud.fm-mogol.sbeok.t-flac16\garcia1963-02-23t02.flac | B129: | | C129: Roll In My Sweet Baby's Arms | D129: |
A130: Z:\Jerry Garcia\1960-1969\jg1963-02-23.004501.wb.aud.fm-mogol.sbeok.t-flac16\garcia1963-02-23t03.flac | B130: | | C130: Jerry's Breakdown (1963) | D130: |
A131: Z:\Jerry Garcia\1960-1969\jg1963-02-23.004501.wb.aud.fm-mogol.sbeok.t-flac16\garcia1963-02-23t04.flac | B131: | | C131: Standing In The Need Of Prayer | D131: |
A132: Z:\Jerry Garcia\1960-1969\jg1963-02-23.004501.wb.aud.fm-mogol.sbeok.t-flac16\garcia1963-02-23t05.flac | B132: | | C132: Mule Skinner Blues | D132: |
A133: Z:\Jerry Garcia\1960-1969\jg1963-02-23.004501.wb.aud.fm-mogol.sbeok.t-flac16\garcia1963-02-23t06.flac | B133: | | C133: Instrumental | D133: |
A134: Z:\Jerry Garcia\1960-1969\jg1963-02-23.004501.wb.aud.fm-mogol.sbeok.t-flac16\garcia1963-02-23t07.flac | B134: | | C134: Pike County Breakdown | D134: |
A135: Z:\Jerry Garcia\1960-1969\jg1963-02-23.004501.wb.aud.fm-mogol.sbeok.t-flac16\garcia1963-02-23t08.flac | B135: | | D135: |
A136: Z:\Jerry Garcia\1960-1969\jg1963-02-23.004501.wb.aud.fm-mogol.sbeok.t-flac16\garcia1963-02-23t09.flac | B136: | | C136: We Shall Not Be Moved | D136: |
A137: Z:\Jerry Garcia\1960-1969\jg1963-05-04.013993.jgsg.fm.t-flac16\jg1963-05-04d1t01.flac | B137: | | C137: Deep Elem Blues | D137: |
A138: Z:\Jerry Garcia\1960-1969\jg1963-05-04.013993.jgsg.fm.t-flac16\jg1963-05-04d1t02.flac | B138: | | C138: Will The Weaver | D138: |
A139: Z:\Jerry Garcia\1960-1969\jg1963-05-04.013993.jgsg.fm.t-flac16\jg1963-05-04d1t03.flac | B139: | | C139: I Truly Understand | D139: |
A140: Z:\Jerry Garcia\1960-1969\jg1963-05-04.013993.jgsg.fm.t-flac16\jg1963-05-04d1t04.flac | B140: | | C140: All The Good Times Are Past And Gone | D140: |
A141: Z:\Jerry Garcia\1960-1969\jg1963-05-04.013993.jgsg.fm.t-flac16\jg1963-05-04d1t05.flac | B141: | | C141: Long Black Veil | D141: |
A142: Z:\Jerry Garcia\1960-1969\jg1963-05-04.013993.jgsg.fm.t-flac16\jg1963-05-04d1t06.flac | B142: | | C142: The Man Who Wrote Home Sweet Home Never Was a Married Man | D142: |
A143: Z:\Jerry Garcia\1960-1969\jg1963-05-04.013993.jgsg.fm.t-flac16\jg1963-05-04d1t07.flac | B143: | | C143: Keno The Rent Man | D143: |
A144: Z:\Jerry Garcia\1960-1969\jg1963-05-04.013993.jgsg.fm.t-flac16\jg1963-05-04d1t08.flac | B144: | | C144: Foggy Mountain Top | D144: |
A145: Z:\Jerry Garcia\1960-1969\jg1964-03-06.017914.bmb.sbd.backus-wagner.sbeok.t-flac16\bmb1964-03-06t01.flac | B145: | | C145: Salt Creek | D145: |
A146: Z:\Jerry Garcia\1960-1969\jg1964-03-06.017914.bmb.sbd.backus-wagner.sbeok.t-flac16\bmb1964-03-06t02.flac | B146: | | C146: Katie Kline | D146: |
A147: Z:\Jerry Garcia\1960-1969\jg1964-03-06.017914.bmb.sbd.backus-wagner.sbeok.t-flac16\bmb1964-03-06t03.flac | B147: | | C147: Introduction | D147: |
...
