Workbook

Sheet releases
A1: orig | B1: path | C1: song_orig | D1: segue | E1: song1 | F1: song2 | G1: song3 | H1: song4
A2: 1 | B2: Z:\Grateful Dead\# Dick's Picks #\01 - 1973-12-19 [Curtis Hixon Hall, Tampa, FL]\01 Here Comes Sunshine.flac | C2: Here Comes Sunshine | D2: =IF(RIGHT(TRIM(C2),2)="->",">",IF(RIGHT(TRIM(C2),1)=">",">","")) | E2: =LOWER(TRIM(SUBSTITUTE(IF(RIGHT(TRIM(C2),2)="->",LEFT(TRIM(C2),LEN(TRIM(C2))-2),IF(RIGHT(TRIM(C2),1)=">",LEFT(TRIM(C2),LEN(TRIM(C2))-1),C2)),"//",""))) -> here comes sunshine | F2: here comes sunshine | G2: =_xlfn.IFNA(VLOOKUP(F2,songs!$B$1:$C$1539, 2, FALSE),"") -> Here Comes Sunshine | H2: Here Comes Sunshine
A3: 2 | B3: Z:\Grateful Dead\# Dick's Picks #\01 - 1973-12-19 [Curtis Hixon Hall, Tampa, FL]\02 Big River.flac | C3: Big River | D3: =IF(RIGHT(TRIM(C3),2)="->",">",IF(RIGHT(TRIM(C3),1)=">",">","")) | E3: =LOWER(TRIM(SUBSTITUTE(IF(RIGHT(TRIM(C3),2)="->",LEFT(TRIM(C3),LEN(TRIM(C3))-2),IF(RIGHT(TRIM(C3),1)=">",LEFT(TRIM(C3),LEN(TRIM(C3))-1),C3)),"//",""))) -> big river | F3: big river | G3: =_xlfn.IFNA(VLOOKUP(F3,songs!$B$1:$C$1539, 2, FALSE),"") -> Big River | H3: Big River
A4: 3 | B4: Z:\Grateful Dead\# Dick's Picks #\01 - 1973-12-19 [Curtis Hixon Hall, Tampa, FL]\03 Mississippi Half-Step Uptown Toodleloo.flac | C4: Mississippi Half-Step Uptown Toodleloo | D4: =IF(RIGHT(TRIM(C4),2)="->",">",IF(RIGHT(TRIM(C4),1)=">",">","")) | E4: =LOWER(TRIM(SUBSTITUTE(IF(RIGHT(TRIM(C4),2)="->",LEFT(TRIM(C4),LEN(TRIM(C4))-2),IF(RIGHT(TRIM(C4),1)=">",LEFT(TRIM(C4),LEN(TRIM(C4))-1),C4)),"//",""))) -> mississippi half-step uptown toodleloo | F4: mississippi half-step uptown toodeloo | G4: =_xlfn.IFNA(VLOOKUP(F4,songs!$B$1:$C$1539, 2, FALSE),"") -> Mississippi Half-Step Uptown Toodeloo
A5: 4 | B5: Z:\Grateful Dead\# Dick's Picks #\01 - 1973-12-19 [Curtis Hixon Hall, Tampa, FL]\04 Weather Report Suite.flac | C5: Weather Report Suite | D5: =IF(RIGHT(TRIM(C5),2)="->",">",IF(RIGHT(TRIM(C5),1)=">",">","")) | E5: =LOWER(TRIM(SUBSTITUTE(IF(RIGHT(TRIM(C5),2)="->",LEFT(TRIM(C5),LEN(TRIM(C5))-2),IF(RIGHT(TRIM(C5),1)=">",LEFT(TRIM(C5),LEN(TRIM(C5))-1),C5)),"//",""))) -> weather report suite | F5: weather report suite prelude > weather report suite part 1 | G5: =_xlfn.IFNA(VLOOKUP(F5,songs!$B$1:$C$1539, 2, FALSE),"") -> Weather Report Suite Prelude > Weather Report Suite Part 1
A6: 5 | B6: Z:\Grateful Dead\# Dick's Picks #\01 - 1973-12-19 [Curtis Hixon Hall, Tampa, FL]\05 Big Railroad Blues.flac | C6: Big Railroad Blues | D6: =IF(RIGHT(TRIM(C6),2)="->",">",IF(RIGHT(TRIM(C6),1)=">",">","")) | E6: =LOWER(TRIM(SUBSTITUTE(IF(RIGHT(TRIM(C6),2)="->",LEFT(TRIM(C6),LEN(TRIM(C6))-2),IF(RIGHT(TRIM(C6),1)=">",LEFT(TRIM(C6),LEN(TRIM(C6))-1),C6)),"//",""))) -> big railroad blues | F6: big railroad blues | G6: =_xlfn.IFNA(VLOOKUP(F6,songs!$B$1:$C$1539, 2, FALSE),"") -> Big Railroad Blues | H6: Big Railroad Blues
A7: 6 | B7: Z:\Grateful Dead\# Dick's Picks #\01 - 1973-12-19 [Curtis Hixon Hall, Tampa, FL]\06 Playing in the Band.flac | C7: Playing in the Band | D7: =IF(RIGHT(TRIM(C7),2)="->",">",IF(RIGHT(TRIM(C7),1)=">",">","")) | E7: =LOWER(TRIM(SUBSTITUTE(IF(RIGHT(TRIM(C7),2)="->",LEFT(TRIM(C7),LEN(TRIM(C7))-2),IF(RIGHT(TRIM(C7),1)=">",LEFT(TRIM(C7),LEN(TRIM(C7))-1),C7)),"//",""))) -> playing in the band | F7: playing in the band | G7: =_xlfn.IFNA(VLOOKUP(F7,songs!$B$1:$C$1539, 2, FALSE),"") -> Playing In The Band | H7: Playing In The Band
A8: 7 | B8: Z:\Grateful Dead\# Dick's Picks #\01 - 1973-12-19 [Curtis Hixon Hall, Tampa, FL]\07 He's Gone.flac | C8: He's Gone | D8: =IF(RIGHT(TRIM(C8),2)="->",">",IF(RIGHT(TRIM(C8),1)=">",">","")) | E8: =LOWER(TRIM(SUBSTITUTE(IF(RIGHT(TRIM(C8),2)="->",LEFT(TRIM(C8),LEN(TRIM(C8))-2),IF(RIGHT(TRIM(C8),1)=">",LEFT(TRIM(C8),LEN(TRIM(C8))-1),C8)),"//",""))) -> he's gone | F8: he's gone | G8: =_xlfn.IFNA(VLOOKUP(F8,songs!$B$1:$C$1539, 2, FALSE),"") -> He's Gone | H8: He's Gone
A9: 8 | B9: Z:\Grateful Dead\# Dick's Picks #\01 - 1973-12-19 [Curtis Hixon Hall, Tampa, FL]\08 Truckin'.flac | C9: Truckin' | D9: =IF(RIGHT(TRIM(C9),2)="->",">",IF(RIGHT(TRIM(C9),1)=">",">","")) | E9: =LOWER(TRIM(SUBSTITUTE(IF(RIGHT(TRIM(C9),2)="->",LEFT(TRIM(C9),LEN(TRIM(C9))-2),IF(RIGHT(TRIM(C9),1)=">",LEFT(TRIM(C9),LEN(TRIM(C9))-1),C9)),"//",""))) -> truckin' | F9: truckin' | G9: =_xlfn.IFNA(VLOOKUP(F9,songs!$B$1:$C$1539, 2, FALSE),"") -> Truckin' | H9: Truckin'
A10: 9 | B10: Z:\Grateful Dead\# Dick's Picks #\01 - 1973-12-19 [Curtis Hixon Hall, Tampa, FL]\09 Nobody's Fault But Mine.flac | C10: Nobody's Fault But Mine | D10: =IF(RIGHT(TRIM(C10),2)="->",">",IF(RIGHT(TRIM(C10),1)=">",">","")) | E10: =LOWER(TRIM(SUBSTITUTE(IF(RIGHT(TRIM(C10),2)="->",LEFT(TRIM(C10),LEN(TRIM(C10))-2),IF(RIGHT(TRIM(C10),1)=">",LEFT(TRIM(C10),LEN(TRIM(C10))-1),C10)),"//",""))) -> nobody's fault but mine | F10: nobody's fault but mine | G10: =_xlfn.IFNA(VLOOKUP(F10,songs!$B$1:$C$1539, 2, FALSE),"") -> Nobody's Fault But Mine | H10: Nobody's Fault But Mine
A11: 10 | B11: Z:\Grateful Dead\# Dick's Picks #\01 - 1973-12-19 [Curtis Hixon Hall, Tampa, FL]\10 Jam.flac | C11: Jam | D11: =IF(RIGHT(TRIM(C11),2)="->",">",IF(RIGHT(TRIM(C11),1)=">",">","")) | E11: =LOWER(TRIM(SUBSTITUTE(IF(RIGHT(TRIM(C11),2)="->",LEFT(TRIM(C11),LEN(TRIM(C11))-2),IF(RIGHT(TRIM(C11),1)=">",LEFT(TRIM(C11),LEN(TRIM(C11))-1),C11)),"//",""))) -> jam | F11: jam | G11: =_xlfn.IFNA(VLOOKUP(F11,songs!$B$1:$C$1539, 2, FALSE),"") -> Jam | H11: Jam
A12: 11 | B12: Z:\Grateful Dead\# Dick's Picks #\01 - 1973-12-19 [Curtis Hixon Hall, Tampa, FL]\11 Other One.flac | C12: Other One | D12: =IF(RIGHT(TRIM(C12),2)="->",">",IF(RIGHT(TRIM(C12),1)=">",">","")) | E12: =LOWER(TRIM(SUBSTITUTE(IF(RIGHT(TRIM(C12),2)="->",LEFT(TRIM(C12),LEN(TRIM(C12))-2),IF(RIGHT(TRIM(C12),1)=">",LEFT(TRIM(C12),LEN(TRIM(C12))-1),C12)),"//",""))) -> other one | F12: the other one | G12: =_xlfn.IFNA(VLOOKUP(F12,songs!$B$1:$C$1539, 2, FALSE),"") -> The Other One
A13: 12 | B13: Z:\Grateful Dead\# Dick's Picks #\01 - 1973-12-19 [Curtis Hixon Hall, Tampa, FL]\12 Jam.flac | C13: Jam | D13: =IF(RIGHT(TRIM(C13),2)="->",">",IF(RIGHT(TRIM(C13),1)=">",">","")) | E13: =LOWER(TRIM(SUBSTITUTE(IF(RIGHT(TRIM(C13),2)="->",LEFT(TRIM(C13),LEN(TRIM(C13))-2),IF(RIGHT(TRIM(C13),1)=">",LEFT(TRIM(C13),LEN(TRIM(C13))-1),C13)),"//",""))) -> jam | F13: jam | G13: =_xlfn.IFNA(VLOOKUP(F13,songs!$B$1:$C$1539, 2, FALSE),"") -> Jam | H13: Jam
A14: 13 | B14: Z:\Grateful Dead\# Dick's Picks #\01 - 1973-12-19 [Curtis Hixon Hall, Tampa, FL]\13 Stella Blue.flac | C14: Stella Blue | D14: =IF(RIGHT(TRIM(C14),2)="->",">",IF(RIGHT(TRIM(C14),1)=">",">","")) | E14: =LOWER(TRIM(SUBSTITUTE(IF(RIGHT(TRIM(C14),2)="->",LEFT(TRIM(C14),LEN(TRIM(C14))-2),IF(RIGHT(TRIM(C14),1)=">",LEFT(TRIM(C14),LEN(TRIM(C14))-1),C14)),"//",""))) -> stella blue | F14: stella blue | G14: =_xlfn.IFNA(VLOOKUP(F14,songs!$B$1:$C$1539, 2, FALSE),"") -> Stella Blue | H14: Stella Blue
A15: 14 | B15: Z:\Grateful Dead\# Dick's Picks #\01 - 1973-12-19 [Curtis Hixon Hall, Tampa, FL]\14 Around and Around.flac | C15: Around and Around | D15: =IF(RIGHT(TRIM(C15),2)="->",">",IF(RIGHT(TRIM(C15),1)=">",">","")) | E15: =LOWER(TRIM(SUBSTITUTE(IF(RIGHT(TRIM(C15),2)="->",LEFT(TRIM(C15),LEN(TRIM(C15))-2),IF(RIGHT(TRIM(C15),1)=">",LEFT(TRIM(C15),LEN(TRIM(C15))-1),C15)),"//",""))) -> around and around | F15: around and around | G15: =_xlfn.IFNA(VLOOKUP(F15,songs!$B$1:$C$1539, 2, FALSE),"") -> Around And Around | H15: Around And Around
A16: 15 | B16: Z:\Grateful Dead\# Dick's Picks #\02 - 1971-10-31 [Ohio Theatre, Columbus, OH]\01 Dark Star-Jam.flac | C16: Dark Star-Jam | D16: =IF(RIGHT(TRIM(C16),2)="->",">",IF(RIGHT(TRIM(C16),1)=">",">","")) | E16: =LOWER(TRIM(SUBSTITUTE(IF(RIGHT(TRIM(C16),2)="->",LEFT(TRIM(C16),LEN(TRIM(C16))-2),IF(RIGHT(TRIM(C16),1)=">",LEFT(TRIM(C16),LEN(TRIM(C16))-1),C16)),"//",""))) -> dark star-jam | F16: dark star | G16: =_xlfn.IFNA(VLOOKUP(F16,songs!$B$1:$C$1539, 2, FALSE),"") -> Dark Star
A17: 16 | B17: Z:\Grateful Dead\# Dick's Picks #\02 - 1971-10-31 [Ohio Theatre, Columbus, OH]\02 Sugar Magnolia.flac | C17: Sugar Magnolia | D17: =IF(RIGHT(TRIM(C17),2)="->",">",IF(RIGHT(TRIM(C17),1)=">",">","")) | E17: =LOWER(TRIM(SUBSTITUTE(IF(RIGHT(TRIM(C17),2)="->",LEFT(TRIM(C17),LEN(TRIM(C17))-2),IF(RIGHT(TRIM(C17),1)=">",LEFT(TRIM(C17),LEN(TRIM(C17))-1),C17)),"//",""))) -> sugar magnolia | F17: sugar magnolia | G17: =_xlfn.IFNA(VLOOKUP(F17,songs!$B$1:$C$1539, 2, FALSE),"") -> Sugar Magnolia | H17: Sugar Magnolia
A18: 17 | B18: Z:\Grateful Dead\# Dick's Picks #\02 - 1971-10-31 [Ohio Theatre, Columbus, OH]\03 St. Stephen.flac | C18: St. Stephen | D18: =IF(RIGHT(TRIM(C18),2)="->",">",IF(RIGHT(TRIM(C18),1)=">",">","")) | E18: =LOWER(TRIM(SUBSTITUTE(IF(RIGHT(TRIM(C18),2)="->",LEFT(TRIM(C18),LEN(TRIM(C18))-2),IF(RIGHT(TRIM(C18),1)=">",LEFT(TRIM(C18),LEN(TRIM(C18))-1),C18)),"//",""))) -> st. stephen | F18: saint stephen | G18: =_xlfn.IFNA(VLOOKUP(F18,songs!$B$1:$C$1539, 2, FALSE),"") -> Saint Stephen
A19: 18 | B19: Z:\Grateful Dead\# Dick's Picks #\02 - 1971-10-31 [Ohio Theatre, Columbus, OH]\04 Not Fade Away.flac | C19: Not Fade Away | D19: =IF(RIGHT(TRIM(C19),2)="->",">",IF(RIGHT(TRIM(C19),1)=">",">","")) | E19: =LOWER(TRIM(SUBSTITUTE(IF(RIGHT(TRIM(C19),2)="->",LEFT(TRIM(C19),LEN(TRIM(C19))-2),IF(RIGHT(TRIM(C19),1)=">",LEFT(TRIM(C19),LEN(TRIM(C19))-1),C19)),"//",""))) -> not fade away | F19: not fade away | G19: =_xlfn.IFNA(VLOOKUP(F19,songs!$B$1:$C$1539, 2, FALSE),"") -> Not Fade Away | H19: Not Fade Away
A20: 19 | B20: Z:\Grateful Dead\# Dick's Picks #\02 - 1971-10-31 [Ohio Theatre, Columbus, OH]\05 Goin' Down the Road Feeling Bad.flac | C20: Goin' Down the Road Feeling Bad | D20: =IF(RIGHT(TRIM(C20),2)="->",">",IF(RIGHT(TRIM(C20),1)=">",">","")) | E20: =LOWER(TRIM(SUBSTITUTE(IF(RIGHT(TRIM(C20),2)="->",LEFT(TRIM(C20),LEN(TRIM(C20))-2),IF(RIGHT(TRIM(C20),1)=">",LEFT(TRIM(C20),LEN(TRIM(C20))-1),C20)),"//",""))) -> goin' down the road feeling bad | F20: goin' down the road feelin' bad | G20: =_xlfn.IFNA(VLOOKUP(F20,songs!$B$1:$C$1539, 2, FALSE),"") -> Goin' Down The Road Feelin' Bad
A21: 20 | B21: Z:\Grateful Dead\# Dick's Picks #\02 - 1971-10-31 [Ohio Theatre, Columbus, OH]\06 Not Fade Away.flac | C21: Not Fade Away | D21: =IF(RIGHT(TRIM(C21),2)="->",">",IF(RIGHT(TRIM(C21),1)=">",">","")) | E21: =LOWER(TRIM(SUBSTITUTE(IF(RIGHT(TRIM(C21),2)="->",LEFT(TRIM(C21),LEN(TRIM(C21))-2),IF(RIGHT(TRIM(C21),1)=">",LEFT(TRIM(C21),LEN(TRIM(C21))-1),C21)),"//",""))) -> not fade away | F21: not fade away | G21: =_xlfn.IFNA(VLOOKUP(F21,songs!$B$1:$C$1539, 2, FALSE),"") -> Not Fade Away | H21: Not Fade Away
A22: 21 | B22: Z:\Grateful Dead\# Dick's Picks #\02 - 1971-10-31 [Ohio Theatre, Columbus, OH] 24 Bit (96-2) Vinyl rip\01 - Dark Star - Jam.flac | C22: Dark Star/Jam | D22: =IF(RIGHT(TRIM(C22),2)="->",">",IF(RIGHT(TRIM(C22),1)=">",">","")) | E22: =LOWER(TRIM(SUBSTITUTE(IF(RIGHT(TRIM(C22),2)="->",LEFT(TRIM(C22),LEN(TRIM(C22))-2),IF(RIGHT(TRIM(C22),1)=">",LEFT(TRIM(C22),LEN(TRIM(C22))-1),C22)),"//",""))) -> dark star/jam | F22: dark star | G22: =_xlfn.IFNA(VLOOKUP(F22,songs!$B$1:$C$1539, 2, FALSE),"") -> Dark Star
A23: 22 | B23: Z:\Grateful Dead\# Dick's Picks #\02 - 1971-10-31 [Ohio Theatre, Columbus, OH] 24 Bit (96-2) Vinyl rip\02 - Sugar Magnolia.flac | C23: Sugar Magnolia | D23: =IF(RIGHT(TRIM(C23),2)="->",">",IF(RIGHT(TRIM(C23),1)=">",">","")) | E23: =LOWER(TRIM(SUBSTITUTE(IF(RIGHT(TRIM(C23),2)="->",LEFT(TRIM(C23),LEN(TRIM(C23))-2),IF(RIGHT(TRIM(C23),1)=">",LEFT(TRIM(C23),LEN(TRIM(C23))-1),C23)),"//",""))) -> sugar magnolia | F23: sugar magnolia | G23: =_xlfn.IFNA(VLOOKUP(F23,songs!$B$1:$C$1539, 2, FALSE),"") -> Sugar Magnolia | H23: Sugar Magnolia
A24: 23 | B24: Z:\Grateful Dead\# Dick's Picks #\02 - 1971-10-31 [Ohio Theatre, Columbus, OH] 24 Bit (96-2) Vinyl rip\03 - St. Stephen.flac | C24: St. Stephen | D24: =IF(RIGHT(TRIM(C24),2)="->",">",IF(RIGHT(TRIM(C24),1)=">",">","")) | E24: =LOWER(TRIM(SUBSTITUTE(IF(RIGHT(TRIM(C24),2)="->",LEFT(TRIM(C24),LEN(TRIM(C24))-2),IF(RIGHT(TRIM(C24),1)=">",LEFT(TRIM(C24),LEN(TRIM(C24))-1),C24)),"//",""))) -> st. stephen | F24: saint stephen | G24: =_xlfn.IFNA(VLOOKUP(F24,songs!$B$1:$C$1539, 2, FALSE),"") -> Saint Stephen
A25: 24 | B25: Z:\Grateful Dead\# Dick's Picks #\02 - 1971-10-31 [Ohio Theatre, Columbus, OH] 24 Bit (96-2) Vinyl rip\04 - Not Fade Away.flac | C25: Not Fade Away | D25: =IF(RIGHT(TRIM(C25),2)="->",">",IF(RIGHT(TRIM(C25),1)=">",">","")) | E25: =LOWER(TRIM(SUBSTITUTE(IF(RIGHT(TRIM(C25),2)="->",LEFT(TRIM(C25),LEN(TRIM(C25))-2),IF(RIGHT(TRIM(C25),1)=">",LEFT(TRIM(C25),LEN(TRIM(C25))-1),C25)),"//",""))) -> not fade away | F25: not fade away | G25: =_xlfn.IFNA(VLOOKUP(F25,songs!$B$1:$C$1539, 2, FALSE),"") -> Not Fade Away | H25: Not Fade Away
A26: 25 | B26: Z:\Grateful Dead\# Dick's Picks #\02 - 1971-10-31 [Ohio Theatre, Columbus, OH] 24 Bit (96-2) Vinyl rip\05 - Goin' Down The Road Feeling Bad.flac | C26: Goin' Down The Road Feeling Bad | D26: =IF(RIGHT(TRIM(C26),2)="->",">",IF(RIGHT(TRIM(C26),1)=">",">","")) | E26: =LOWER(TRIM(SUBSTITUTE(IF(RIGHT(TRIM(C26),2)="->",LEFT(TRIM(C26),LEN(TRIM(C26))-2),IF(RIGHT(TRIM(C26),1)=">",LEFT(TRIM(C26),LEN(TRIM(C26))-1),C26)),"//",""))) -> goin' down the road feeling bad | F26: goin' down the road feelin' bad | G26: =_xlfn.IFNA(VLOOKUP(F26,songs!$B$1:$C$1539, 2, FALSE),"") -> Goin' Down The Road Feelin' Bad
A27: 26 | B27: Z:\Grateful Dead\# Dick's Picks #\02 - 1971-10-31 [Ohio Theatre, Columbus, OH] 24 Bit (96-2) Vinyl rip\06 - Not Fade Away.flac | C27: Not Fade Away | D27: =IF(RIGHT(TRIM(C27),2)="->",">",IF(RIGHT(TRIM(C27),1)=">",">","")) | E27: =LOWER(TRIM(SUBSTITUTE(IF(RIGHT(TRIM(C27),2)="->",LEFT(TRIM(C27),LEN(TRIM(C27))-2),IF(RIGHT(TRIM(C27),1)=">",LEFT(TRIM(C27),LEN(TRIM(C27))-1),C27)),"//",""))) -> not fade away | F27: not fade away | G27: =_xlfn.IFNA(VLOOKUP(F27,songs!$B$1:$C$1539, 2, FALSE),"") -> Not Fade Away | H27: Not Fade Away
A28: 27 | B28: Z:\Grateful Dead\# Dick's Picks #\03 - 1977-05-22 [Sportatorium, Pembroke Pines, FL]\101 Funiculì Funicula.flac | C28: Funiculì Funicula | D28: =IF(RIGHT(TRIM(C28),2)="->",">",IF(RIGHT(TRIM(C28),1)=">",">","")) | E28: =LOWER(TRIM(SUBSTITUTE(IF(RIGHT(TRIM(C28),2)="->",LEFT(TRIM(C28),LEN(TRIM(C28))-2),IF(RIGHT(TRIM(C28),1)=">",LEFT(TRIM(C28),LEN(TRIM(C28))-1),C28)),"//",""))) -> funiculì funicula | F28: funiculì funicula | G28: Funiculi, Funicula
A29: 28 | B29: Z:\Grateful Dead\# Dick's Picks #\03 - 1977-05-22 [Sportatorium, Pembroke Pines, FL]\102 The Music Never Stopped.flac | C29: The Music Never Stopped | D29: =IF(RIGHT(TRIM(C29),2)="->",">",IF(RIGHT(TRIM(C29),1)=">",">","")) | E29: =LOWER(TRIM(SUBSTITUTE(IF(RIGHT(TRIM(C29),2)="->",LEFT(TRIM(C29),LEN(TRIM(C29))-2),IF(RIGHT(TRIM(C29),1)=">",LEFT(TRIM(C29),LEN(TRIM(C29))-1),C29)),"//",""))) -> the music never stopped | F29: the music never stopped | G29: =_xlfn.IFNA(VLOOKUP(F29,songs!$B$1:$C$1539, 2, FALSE),"") -> The Music Never Stopped | H29: The Music Never Stopped
A30: 29 | B30: Z:\Grateful Dead\# Dick's Picks #\03 - 1977-05-22 [Sportatorium, Pembroke Pines, FL]\103 Sugaree.flac | C30: Sugaree | D30: =IF(RIGHT(TRIM(C30),2)="->",">",IF(RIGHT(TRIM(C30),1)=">",">","")) | E30: =LOWER(TRIM(SUBSTITUTE(IF(RIGHT(TRIM(C30),2)="->",LEFT(TRIM(C30),LEN(TRIM(C30))-2),IF(RIGHT(TRIM(C30),1)=">",LEFT(TRIM(C30),LEN(TRIM(C30))-1),C30)),"//",""))) -> sugaree | F30: sugaree | G30: =_xlfn.IFNA(VLOOKUP(F30,songs!$B$1:$C$1539, 2, FALSE),"") -> Sugaree | H30: Sugaree
A31: 30 | B31: Z:\Grateful Dead\# Dick's Picks #\03 - 1977-05-22 [Sportatorium, Pembroke Pines, FL]\104 Lazy Lightning.flac | C31: Lazy Lightning | D31: =IF(RIGHT(TRIM(C31),2)="->",">",IF(RIGHT(TRIM(C31),1)=">",">","")) | E31: =LOWER(TRIM(SUBSTITUTE(IF(RIGHT(TRIM(C31),2)="->",LEFT(TRIM(C31),LEN(TRIM(C31))-2),IF(RIGHT(TRIM(C31),1)=">",LEFT(TRIM(C31),LEN(TRIM(C31))-1),C31)),"//",""))) -> lazy lightning | F31: lazy lightning | G31: =_xlfn.IFNA(VLOOKUP(F31,songs!$B$1:$C$1539, 2, FALSE),"") -> Lazy Lightning | H31: Lazy Lightning
A32: 31 | B32: Z:\Grateful Dead\# Dick's Picks #\03 - 1977-05-22 [Sportatorium, Pembroke Pines, FL]\105 Supplication.flac | C32: Supplication | D32: =IF(RIGHT(TRIM(C32),2)="->",">",IF(RIGHT(TRIM(C32),1)=">",">","")) | E32: =LOWER(TRIM(SUBSTITUTE(IF(RIGHT(TRIM(C32),2)="->",LEFT(TRIM(C32),LEN(TRIM(C32))-2),IF(RIGHT(TRIM(C32),1)=">",LEFT(TRIM(C32),LEN(TRIM(C32))-1),C32)),"//",""))) -> supplication | F32: supplication | G32: =_xlfn.IFNA(VLOOKUP(F32,songs!$B$1:$C$1539, 2, FALSE),"") -> Supplication | H32: Supplication
A33: 32 | B33: Z:\Grateful Dead\# Dick's Picks #\03 - 1977-05-22 [Sportatorium, Pembroke Pines, FL]\106 Dancing in the Street.flac | C33: Dancing in the Street | D33: =IF(RIGHT(TRIM(C33),2)="->",">",IF(RIGHT(TRIM(C33),1)=">",">","")) | E33: =LOWER(TRIM(SUBSTITUTE(IF(RIGHT(TRIM(C33),2)="->",LEFT(TRIM(C33),LEN(TRIM(C33))-2),IF(RIGHT(TRIM(C33),1)=">",LEFT(TRIM(C33),LEN(TRIM(C33))-1),C33)),"//",""))) -> dancing in the street | F33: dancin' in the streets | G33: =_xlfn.IFNA(VLOOKUP(F33,songs!$B$1:$C$1539, 2, FALSE),"") -> Dancin' In The Streets
A34: 33 | B34: Z:\Grateful Dead\# Dick's Picks #\03 - 1977-05-22 [Sportatorium, Pembroke Pines, FL]\107 Help on the Way.flac | C34: Help on the Way | D34: =IF(RIGHT(TRIM(C34),2)="->",">",IF(RIGHT(TRIM(C34),1)=">",">","")) | E34: =LOWER(TRIM(SUBSTITUTE(IF(RIGHT(TRIM(C34),2)="->",LEFT(TRIM(C34),LEN(TRIM(C34))-2),IF(RIGHT(TRIM(C34),1)=">",LEFT(TRIM(C34),LEN(TRIM(C34))-1),C34)),"//",""))) -> help on the way | F34: help on the way | G34: =_xlfn.IFNA(VLOOKUP(F34,songs!$B$1:$C$1539, 2, FALSE),"") -> Help On The Way | H34: Help On The Way
A35: 34 | B35: Z:\Grateful Dead\# Dick's Picks #\03 - 1977-05-22 [Sportatorium, Pembroke Pines, FL]\108 Slipknot!.flac | C35: Slipknot! | D35: =IF(RIGHT(TRIM(C35),2)="->",">",IF(RIGHT(TRIM(C35),1)=">",">","")) | E35: =LOWER(TRIM(SUBSTITUTE(IF(RIGHT(TRIM(C35),2)="->",LEFT(TRIM(C35),LEN(TRIM(C35))-2),IF(RIGHT(TRIM(C35),1)=">",LEFT(TRIM(C35),LEN(TRIM(C35))-1),C35)),"//",""))) -> slipknot! | F35: slipknot! | G35: =_xlfn.IFNA(VLOOKUP(F35,songs!$B$1:$C$1539, 2, FALSE),"") -> Slipknot! | H35: Slipknot!
A36: 35 | B36: Z:\Grateful Dead\# Dick's Picks #\03 - 1977-05-22 [Sportatorium, Pembroke Pines, FL]\109 Franklin's Tower.flac | C36: Franklin's Tower | D36: =IF(RIGHT(TRIM(C36),2)="->",">",IF(RIGHT(TRIM(C36),1)=">",">","")) | E36: =LOWER(TRIM(SUBSTITUTE(IF(RIGHT(TRIM(C36),2)="->",LEFT(TRIM(C36),LEN(TRIM(C36))-2),IF(RIGHT(TRIM(C36),1)=">",LEFT(TRIM(C36),LEN(TRIM(C36))-1),C36)),"//",""))) -> franklin's tower | F36: franklin's tower | G36: =_xlfn.IFNA(VLOOKUP(F36,songs!$B$1:$C$1539, 2, FALSE),"") -> Franklin's Tower | H36: Franklin's Tower
A37: 36 | B37: Z:\Grateful Dead\# Dick's Picks #\03 - 1977-05-22 [Sportatorium, Pembroke Pines, FL]\201 Samson and Delilah.flac | C37: Samson and Delilah | D37: =IF(RIGHT(TRIM(C37),2)="->",">",IF(RIGHT(TRIM(C37),1)=">",">","")) | E37: =LOWER(TRIM(SUBSTITUTE(IF(RIGHT(TRIM(C37),2)="->",LEFT(TRIM(C37),LEN(TRIM(C37))-2),IF(RIGHT(TRIM(C37),1)=">",LEFT(TRIM(C37),LEN(TRIM(C37))-1),C37)),"//",""))) -> samson and delilah | F37: samson and delilah | G37: =_xlfn.IFNA(VLOOKUP(F37,songs!$B$1:$C$1539, 2, FALSE),"") -> Samson And Delilah | H37: Samson And Delilah
A38: 37 | B38: Z:\Grateful Dead\# Dick's Picks #\03 - 1977-05-22 [Sportatorium, Pembroke Pines, FL]\202 Sunrise.flac | C38: Sunrise | D38: =IF(RIGHT(TRIM(C38),2)="->",">",IF(RIGHT(TRIM(C38),1)=">",">","")) | E38: =LOWER(TRIM(SUBSTITUTE(IF(RIGHT(TRIM(C38),2)="->",LEFT(TRIM(C38),LEN(TRIM(C38))-2),IF(RIGHT(TRIM(C38),1)=">",LEFT(TRIM(C38),LEN(TRIM(C38))-1),C38)),"//",""))) -> sunrise | F38: sunrise | G38: =_xlfn.IFNA(VLOOKUP(F38,songs!$B$1:$C$1539, 2, FALSE),"") -> Sunrise | H38: Sunrise
A39: 38 | B39: Z:\Grateful Dead\# Dick's Picks #\03 - 1977-05-22 [Sportatorium, Pembroke Pines, FL]\203 Estimated Prophet.flac | C39: Estimated Prophet | D39: =IF(RIGHT(TRIM(C39),2)="->",">",IF(RIGHT(TRIM(C39),1)=">",">","")) | E39: =LOWER(TRIM(SUBSTITUTE(IF(RIGHT(TRIM(C39),2)="->",LEFT(TRIM(C39),LEN(TRIM(C39))-2),IF(RIGHT(TRIM(C39),1)=">",LEFT(TRIM(C39),LEN(TRIM(C39))-1),C39)),"//",""))) -> estimated prophet | F39: estimated prophet | G39: =_xlfn.IFNA(VLOOKUP(F39,songs!$B$1:$C$1539, 2, FALSE),"") -> Estimated Prophet | H39: Estimated Prophet
A40: 39 | B40: Z:\Grateful Dead\# Dick's Picks #\03 - 1977-05-22 [Sportatorium, Pembroke Pines, FL]\204 Eyes of the World.flac | C40: Eyes of the World | D40: =IF(RIGHT(TRIM(C40),2)="->",">",IF(RIGHT(TRIM(C40),1)=">",">","")) | E40: =LOWER(TRIM(SUBSTITUTE(IF(RIGHT(TRIM(C40),2)="->",LEFT(TRIM(C40),LEN(TRIM(C40))-2),IF(RIGHT(TRIM(C40),1)=">",LEFT(TRIM(C40),LEN(TRIM(C40))-1),C40)),"//",""))) -> eyes of the world | F40: eyes of the world | G40: =_xlfn.IFNA(VLOOKUP(F40,songs!$B$1:$C$1539, 2, FALSE),"") -> Eyes Of The World | H40: Eyes Of The World
...

Sheet songs
A1: 1501 | B1: (back home again in) indiana | C1: (Back Home Again In) Indiana
A2: 500 | B2: (i'm a) road runner | C2: (I'm A) Road Runner
A3: 935 | B3: 16/16 | C3: 16/16
A4: 1629 | B4: 23rd psalm | C4: 23rd Psalm
A5: 35 | B5: 3 o'clock in the morning blues | C5: 3 O'Clock In The Morning Blues
A6: 817 | B6: a cry from the cross | C6: A Cry From The Cross
A7: 1709 | B7: a day in the life | C7: A Day In the Life
A8: 1555 | B8: a good man is hard to find | C8: A Good Man Is Hard To Find
A9: 479 | B9: a good woman's love | C9: A Good Woman's Love
A10: 370 | B10: a hard rain's a-gonna fall | C10: A Hard Rain's A-Gonna Fall
A11: 815 | B11: a little at a time | C11: A Little At A Time
A12: 1213 | B12: a mind to give up livin' | C12: A Mind To Give Up Livin'
... A1539: 894 | B1539: zillionaire | C1539: Zillionaire

Sheet export
A1: Z:\Grateful Dead\# Dick's Picks #\01 - 1973-12-19 [Curtis Hixon Hall, Tampa, FL]\03 Mississippi Half-Step Uptown Toodleloo.flac | B1: | | C1: Mississippi Half-Step Uptown Toodeloo | D1: |
A2: Z:\Grateful Dead\# Dick's Picks #\01 - 1973-12-19 [Curtis Hixon Hall, Tampa, FL]\04 Weather Report Suite.flac | B2: | | C2: Weather Report Suite Prelude > Weather Report Suite Part 1 | D2: |
A3: Z:\Grateful Dead\# Dick's Picks #\01 - 1973-12-19 [Curtis Hixon Hall, Tampa, FL]\11 Other One.flac | B3: | | C3: The Other One | D3: |
A4: Z:\Grateful Dead\# Dick's Picks #\02 - 1971-10-31 [Ohio Theatre, Columbus, OH]\01 Dark Star-Jam.flac | B4: | | C4: Dark Star | D4: |
A5: Z:\Grateful Dead\# Dick's Picks #\02 - 1971-10-31 [Ohio Theatre, Columbus, OH]\03 St. Stephen.flac | B5: | | C5: Saint Stephen | D5: |
A6: Z:\Grateful Dead\# Dick's Picks #\02 - 1971-10-31 [Ohio Theatre, Columbus, OH]\05 Goin' Down the Road Feeling Bad.flac | B6: | | C6: Goin' Down The Road Feelin' Bad | D6: |
A7: Z:\Grateful Dead\# Dick's Picks #\02 - 1971-10-31 [Ohio Theatre, Columbus, OH] 24 Bit (96-2) Vinyl rip\01 - Dark Star - Jam.flac | B7: | | C7: Dark Star | D7: |
A8: Z:\Grateful Dead\# Dick's Picks #\02 - 1971-10-31 [Ohio Theatre, Columbus, OH] 24 Bit (96-2) Vinyl rip\03 - St. Stephen.flac | B8: | | C8: Saint Stephen | D8: |
A9: Z:\Grateful Dead\# Dick's Picks #\02 - 1971-10-31 [Ohio Theatre, Columbus, OH] 24 Bit (96-2) Vinyl rip\05 - Goin' Down The Road Feeling Bad.flac | B9: | | C9: Goin' Down The Road Feelin' Bad | D9: |
A10: Z:\Grateful Dead\# Dick's Picks #\03 - 1977-05-22 [Sportatorium, Pembroke Pines, FL]\101 Funiculì Funicula.flac | B10: | | C10: Funiculi, Funicula | D10: |
A11: Z:\Grateful Dead\# Dick's Picks #\03 - 1977-05-22 [Sportatorium, Pembroke Pines, FL]\106 Dancing in the Street.flac | B11: | | C11: Dancin' In The Streets | D11: |
A12: Z:\Grateful Dead\# Dick's Picks #\03 - 1977-05-22 [Sportatorium, Pembroke Pines, FL]\207 (Walk Me Out in the ) Morning Dew.flac | B12: | | C12: Morning Dew | D12: |
... A76: Z:\Grateful Dead\# Dick's Picks #\20 - 1976-09-25 [Capitol Centre, Landover, MD]\105 Brown-Eyed Women.flac | B76: | | C76: Brown Eyed Women | D76: |
A77: Z:\Grateful Dead\# Dick's Picks #\20 - 1976-09-25 [Capitol Centre, Landover, MD]\201 Lazy Lightnin' -».flac | B77: | | C77: Lazy Lightning | D77: | | E77: >
A78: Z:\Grateful Dead\# Dick's Picks #\20 - 1976-09-25 [Capitol Centre, Landover, MD]\204 Dancing In The Streets.flac | B78: | | C78: Dancin' In The Streets | D78: |
A79: Z:\Grateful Dead\# Dick's Picks #\20 - 1976-09-25 [Capitol Centre, Landover, MD]\207 St. Stephen.flac | B79: | | C79: Saint Stephen | D79: |
A80: Z:\Grateful Dead\# Dick's Picks #\20 - 1976-09-25 [Capitol Centre, Landover, MD]\211 St. Stephen.flac | B80: | | C80: Saint Stephen | D80: |
A81: Z:\Grateful Dead\# Dick's Picks #\20 - 1976-09-28 [Onondaga County War Memorial, Syracuse, NY]\101 Cold Rain & Snow.flac | B81: | | C81: Cold Rain And Snow | D81: |
A82: Z:\Grateful Dead\# Dick's Picks #\20 - 1976-09-28 [Onondaga County War Memorial, Syracuse, NY]\105 New Minglewood Blues.flac | B82: | | C82: Minglewood Blues | D82: |
A83: Z:\Grateful Dead\# Dick's Picks #\20 - 1976-09-28 [Onondaga County War Memorial, Syracuse, NY]\110 Goin Down the Road Feelin Bad.flac | B83: | | C83: Goin' Down The Road Feelin' Bad | D83: |
A84: Z:\Grateful Dead\# Dick's Picks #\20 - 1976-09-28 [Onondaga County War Memorial, Syracuse, NY]\203 Samson & Delilah.flac | B84: | | C84: Samson And Delilah | D84: |
A85: Z:\Grateful Dead\# Dick's Picks #\20 - 1976-09-28 [Onondaga County War Memorial, Syracuse, NY]\209 Dancing in the Streets.flac | B85: | | C85: Dancin' In The Streets | D85: |
A86: Z:\Grateful Dead\# Dick's Picks #\21 - 1985-11-01 [Richmond Coliseum, Richmond, VA]\101 Dancing In The Streets -».flac | B86: | | C86: Dancin' In The Streets | D86: | | E86: >
A87: Z:\Grateful Dead\# Dick's Picks #\21 - 1985-11-01 [Richmond Coliseum, Richmond, VA]\107 Brown-Eyed Women.flac | B87: | | C87: Brown Eyed Women | D87: |
A88: Z:\Grateful Dead\# Dick's Picks #\21 - 1985-11-01 [Richmond Coliseum, Richmond, VA]\213 Keep Your Day Job.flac | B88: | | C88: Day Job | D88: |
A89: Z:\Grateful Dead\# Dick's Picks #\22 - 1968-02-23 [Kings Beach, Lake Tahoe, CA]\202 Good Morning Little School Girl.flac | B89: | | C89: Good Morning Little Schoolgirl | D89: |
A90: Z:\Grateful Dead\# Dick's Picks #\22 - 1968-02-23 [Kings Beach, Lake Tahoe, CA]\203 That's It For The Other One -».flac | B90: | | C90: The Other One | D90: | | E90: >
A91: Z:\Grateful Dead\# Dick's Picks #\22 - 1968-02-23 [Kings Beach, Lake Tahoe, CA]\209 Caution -».flac | B91: | | C91: Caution (Do Not Stop On Tracks) | D91: | | E91: >
A92: Z:\Grateful Dead\# Dick's Picks #\23 - 1972-09-17 [Baltimore Civic Center, Baltimore, MD]\103 Black-Throated Wind.flac | B92: | | C92: Black Throated Wind | D92: |
A93: Z:\Grateful Dead\# Dick's Picks #\24 - 1974-03-23 [Cow Palace, Daly City, CA]\103 Brown-Eyed Women.flac | B93: | | C93: Brown Eyed Women | D93: |
A94: Z:\Grateful Dead\# Dick's Picks #\24 - 1974-03-23 [Cow Palace, Daly City, CA]\104 Black-Throated Wind.flac | B94: | | C94: Black Throated Wind | D94: |
A95: Z:\Grateful Dead\# Dick's Picks #\24 - 1974-03-23 [Cow Palace, Daly City, CA]\109 China Cat Sunflower-».flac | B95: | | C95: China Cat Sunflower | D95: | | E95: >
A96: Z:\Grateful Dead\# Dick's Picks #\24 - 1974-03-23 [Cow Palace, Daly City, CA]\111 Weather Report Suite.flac | B96: | | C96: Weather Report Suite Prelude > Weather Report Suite Part 1 | D96: |
A97: Z:\Grateful Dead\# Dick's Picks #\24 - 1974-03-23 [Cow Palace, Daly City, CA]\204 Uncle John's Band reprise -».flac | B97: | | C97: Uncle John's Band | D97: | | E97: >
A98: Z:\Grateful Dead\# Dick's Picks #\25 - 1978-05-10 [New Haven Coliseum, New Haven, CT]\205 drumz ].flac | B98: | | C98: Drums | D98: | | E98: >
A99: Z:\Grateful Dead\# Dick's Picks #\25 - 1978-05-10 [New Haven Coliseum, New Haven, CT]\206 Other One ].flac | B99: | | C99: The Other One | D99: | | E99: >
A100: Z:\Grateful Dead\# Dick's Picks #\25 - 1978-05-11 [Springfield Civic Centre Arena, Springfield]\106 New Minglewood Blues.flac | B100: | | C100: Minglewood Blues | D100: |
A101: Z:\Grateful Dead\# Dick's Picks #\25 - 1978-05-11 [Springfield Civic Centre Arena, Springfield]\108 Lazy Lightnin' --».flac | B101: | | C101: Lazy Lightning | D101: | | E101: >
A102: Z:\Grateful Dead\# Dick's Picks #\25 - 1978-05-11 [Springfield Civic Centre Arena, Springfield]\203 Dancing In The Streets.flac | B102: | | C102: Dancin' In The Streets | D102: |
A103: Z:\Grateful Dead\# Dick's Picks #\26 - 1969-04-26 [Electric Theatre, Chicago, IL]\101 Duprees Diamond Blues».flac | B103: | | C103: Dupree's Diamond Blues | D103: |
...
